Python 3.10.0 (tags/v3.10.0:b494f59, Oct  4 2021, 19:00:18) [MSC v.1929 64 bit (AMD64)] on win32
Type "help", "copyright", "credits" or "license()" for more information.

=== RESTART: C:\Python310\python_program\file_handling\exception_handling.py ===
enter a value: 5
x is eligible
Exception Error :  division by zero

=== RESTART: C:\Python310\python_program\file_handling\exception_handling.py ===
enter a value: r
Traceback (most recent call last):
  File "C:\Python310\python_program\file_handling\exception_handling.py", line 52, in <module>
    x = int(input("enter a value: "))
ValueError: invalid literal for int() with base 10: 'r'

=== RESTART: C:\Python310\python_program\file_handling\exception_handling.py ===
enter a value: r
invalid input

=== RESTART: C:\Python310\python_program\file_handling\exception_handling.py ===
enter a value: r
Traceback (most recent call last):
  File "C:\Python310\python_program\file_handling\exception_handling.py", line 52, in <module>
    x = int(input("enter a value: "))
ValueError: invalid literal for int() with base 10: 'r'

=== RESTART: C:\Python310\python_program\file_handling\exception_handling.py ===
enter a value: 9
x is eligible
Exception Error :  division by zero

=== RESTART: C:\Python310\python_program\file_handling\exception_handling.py ===
enter a value: 78
x is not Eligible

=== RESTART: C:\Python310\python_program\file_handling\exception_handling.py ===
enter a value: 34
Traceback (most recent call last):
  File "C:\Python310\python_program\file_handling\exception_handling.py", line 53, in <module>
    assert x<10,'age limit should be less than 10'
AssertionError: age limit should be less than 10

During handling of the above exception, another exception occurred:

Traceback (most recent call last):
  File "C:\Python310\python_program\file_handling\exception_handling.py", line 60, in <module>
    print("entered values are :",x,y)
NameError: name 'y' is not defined

=== RESTART: C:\Python310\python_program\file_handling\exception_handling.py ===
enter a value: 11
Traceback (most recent call last):
  File "C:\Python310\python_program\file_handling\exception_handling.py", line 53, in <module>
    assert x<10,'age limit should be less than 10'
AssertionError: age limit should be less than 10

During handling of the above exception, another exception occurred:

Traceback (most recent call last):
  File "C:\Python310\python_program\file_handling\exception_handling.py", line 60, in <module>
    print("entered values are :",x,y)
NameError: name 'y' is not defined

=== RESTART: C:\Python310\python_program\file_handling\exception_handling.py ===
enter a value: 9
x is eligible
Exception Error :  division by zero
entered values are : 9

=== RESTART: C:\Python310\python_program\file_handling\exception_handling.py ===
enter a value: 
Traceback (most recent call last):
  File "C:\Python310\python_program\file_handling\exception_handling.py", line 52, in <module>
    x = int(input("enter a value: "))
ValueError: invalid literal for int() with base 10: ''

During handling of the above exception, another exception occurred:

Traceback (most recent call last):
  File "C:\Python310\python_program\file_handling\exception_handling.py", line 60, in <module>
    print("entered values are :",x)
NameError: name 'x' is not defined

=== RESTART: C:\Python310\python_program\file_handling\exception_handling.py ===
enter a value: r
error :  invalid literal for int() with base 10: 'r'
Traceback (most recent call last):
  File "C:\Python310\python_program\file_handling\exception_handling.py", line 62, in <module>
    print("entered values are :",x)
NameError: name 'x' is not defined

=== RESTART: C:\Python310\python_program\file_handling\exception_handling.py ===
enter a value: r
error :  invalid literal for int() with base 10: 'r'
entered values are : 10

=== RESTART: C:\Python310\python_program\file_handling\exception_handling.py ===
enter x value :r
Exception values are :  invalid literal for int() with base 10: 'r'

=== RESTART: C:\Python310\python_program\file_handling\exception_handling.py ===
enter x value :5
Exception values are :  division by zero

=== RESTART: C:\Python310\python_program\file_handling\exception_handling.py ===
enter a value: r
Except block : Invalid input,enter numbers only

=== RESTART: C:\Python310\python_program\file_handling\exception_handling.py ===
enter a value: 5
Except block : Invalid input,enter numbers only

=== RESTART: C:\Python310\python_program\file_handling\exception_handling.py ===
enter a value: r
divide by zero exception is raised
invalid literal for int() with base 10: 'r'

=== RESTART: C:\Python310\python_program\file_handling\exception_handling.py ===
enter a value: r
Except block : Invalid input,enter numbers only

=== RESTART: C:\Python310\python_program\file_handling\exception_handling.py ===
enter a value: 3
Try block : number is  3
no exception

=== RESTART: C:\Python310\python_program\file_handling\exception_handling.py ===
enter a value: r
Except block : Invalid input,enter numbers only
Traceback (most recent call last):
  File "C:\Python310\python_program\file_handling\exception_handling.py", line 37, in <module>
    print(" entered value is : ",x)
NameError: name 'x' is not defined

=== RESTART: C:\Python310\python_program\file_handling\exception_handling.py ===
enter a value: r
Except block : Invalid input,enter numbers only
 entered value is : 

=== RESTART: C:\Python310\python_program\file_handling\exception_handling.py ===
enter a value: 6
Try block : number is  6
 entered value is :  6

=== RESTART: C:\Python310\python_program\file_handling\exception_handling.py ===
enter a value: 5
Try block : number is  5
 entered value is :  5

=== RESTART: C:\Python310\python_program\file_handling\exception_handling.py ===
enter a value: r
Traceback (most recent call last):
  File "C:\Python310\python_program\file_handling\exception_handling.py", line 32, in <module>
    x = int(input("enter a value: "))
ValueError: invalid literal for int() with base 10: 'r'

During handling of the above exception, another exception occurred:

Traceback (most recent call last):
  File "C:\Python310\python_program\file_handling\exception_handling.py", line 35, in <module>
    print(" entered value is : ",x)
NameError: name 'x' is not defined

=== RESTART: C:\Python310\python_program\file_handling\exception_handling.py ===
enter a value: r
 entered value is : 
Traceback (most recent call last):
  File "C:\Python310\python_program\file_handling\exception_handling.py", line 32, in <module>
    x = int(input("enter a value: "))
ValueError: invalid literal for int() with base 10: 'r'

=== RESTART: C:\Python310\python_program\file_handling\exception_handling.py ===
enter a value: r
 entered value is : 
Traceback (most recent call last):
  File "C:\Python310\python_program\file_handling\exception_handling.py", line 32, in <module>
    x = int(input("enter a value: "))
ValueError: invalid literal for int() with base 10: 'r'

=== RESTART: C:\Python310\python_program\file_handling\exception_handling.py ===
 entered value is : 
Traceback (most recent call last):
  File "C:\Python310\python_program\file_handling\exception_handling.py", line 32, in <module>
    x = char(input("enter a value: "))
NameError: name 'char' is not defined. Did you mean: 'chr'?

=== RESTART: C:\Python310\python_program\file_handling\exception_handling.py ===
enter a value: r
Try block : number is  r
 entered value is : 

=== RESTART: C:\Python310\python_program\file_handling\exception_handling.py ===
 entered value is : 
Traceback (most recent call last):
  File "C:\Python310\python_program\file_handling\exception_handling.py", line 36, in <module>
    z = x/y
ZeroDivisionError: division by zero

=== RESTART: C:\Python310\python_program\file_handling\exception_handling.py ===
division by zero
 entered value is : 
