Python 3.10.0 (tags/v3.10.0:b494f59, Oct  4 2021, 19:00:18) [MSC v.1929 64 bit (AMD64)] on win32
Type "help", "copyright", "credits" or "license()" for more information.

========== RESTART: C:/Python310/python_program/file_handling/read.py ==========
Traceback (most recent call last):
  File "C:/Python310/python_program/file_handling/read.py", line 2, in <module>
    file = open("file1.txt","r")
FileNotFoundError: [Errno 2] No such file or directory: 'file1.txt'

========== RESTART: C:/Python310/python_program/file_handling/read.py ==========
Traceback (most recent call last):
  File "C:/Python310/python_program/file_handling/read.py", line 2, in <module>
    file = open("C:\Python310\python_program\file_handling","r")
OSError: [Errno 22] Invalid argument: 'C:\\Python310\\python_program\x0cile_handling'

========== RESTART: C:/Python310/python_program/file_handling/read.py ==========
Traceback (most recent call last):
  File "C:/Python310/python_program/file_handling/read.py", line 2, in <module>
    file = open("C:\Python310\python_program\file_handling","r")
OSError: [Errno 22] Invalid argument: 'C:\\Python310\\python_program\x0cile_handling'

========== RESTART: C:/Python310/python_program/file_handling/read.py ==========
Traceback (most recent call last):
  File "C:/Python310/python_program/file_handling/read.py", line 2, in <module>
    file = open("C:\Python310\python_program\file_handling\file1.txt","r")
OSError: [Errno 22] Invalid argument: 'C:\\Python310\\python_program\x0cile_handling\x0cile1.txt'

========== RESTART: C:/Python310/python_program/file_handling/read.py ==========
Traceback (most recent call last):
  File "C:/Python310/python_program/file_handling/read.py", line 2, in <module>
    file = open("C:\Python310\python_program\file_handling\file1.txt")
OSError: [Errno 22] Invalid argument: 'C:\\Python310\\python_program\x0cile_handling\x0cile1.txt'

========== RESTART: C:/Python310/python_program/file_handling/read.py ==========
Traceback (most recent call last):
  File "C:/Python310/python_program/file_handling/read.py", line 2, in <module>
    file = open("C:\Python310\python_program\file_handling\file1.txt")
OSError: [Errno 22] Invalid argument: 'C:\\Python310\\python_program\x0cile_handling\x0cile1.txt'

========== RESTART: C:/Python310/python_program/file_handling/read.py ==========
Traceback (most recent call last):
  File "C:/Python310/python_program/file_handling/read.py", line 2, in <module>
    file = open("file.txt")
FileNotFoundError: [Errno 2] No such file or directory: 'file.txt'

========== RESTART: C:/Python310/python_program/file_handling/read.py ==========
Traceback (most recent call last):
  File "C:/Python310/python_program/file_handling/read.py", line 2, in <module>
    file = open("file1.txt")
FileNotFoundError: [Errno 2] No such file or directory: 'file1.txt'

========== RESTART: C:/Python310/python_program/file_handling/read.py ==========
Traceback (most recent call last):
  File "C:/Python310/python_program/file_handling/read.py", line 2, in <module>
    file = open("file1.txt",'r')
FileNotFoundError: [Errno 2] No such file or directory: 'file1.txt'

5========== RESTART: C:/Python310/python_program/file_handling/read.py ==========
Hello World!

welcome to python 



========== RESTART: C:/Python310/python_program/file_handling/read.py ==========
Hello World!

welcome to python 


Hell

========== RESTART: C:/Python310/python_program/file_handling/read.py ==========
Hello World!

welcome to python 


Hell
Hello World!


========== RESTART: C:/Python310/python_program/file_handling/read.py ==========
Hello World!

welcome to python 


Hell
Hello World!

He

========== RESTART: C:/Python310/python_program/file_handling/read.py ==========
He

========== RESTART: C:/Python310/python_program/file_handling/read.py ==========
Hello World!

welcome to python 


He

========== RESTART: C:/Python310/python_program/file_handling/read.py ==========
Hello World!

welcome to python 


Hell
Hello World!

He

========== RESTART: C:/Python310/python_program/file_handling/read.py ==========
Hello World!

welcome to python 


Hell
Hello World!

He
['Hello World!\n', '\n', 'welcome to python \n', '\n']

========== RESTART: C:/Python310/python_program/file_handling/read.py ==========
Hello World!

welcome to python 


Hell
Hello World!

He
['Hello World!\n', '\n', 'welcome to python \n', '\n']

========== RESTART: C:/Python310/python_program/file_handling/read.py ==========
Hello World!

welcome to python 


Hell
Hello World!

He
['Hello World!\n', '\n', 'welcome to python \n', '\n']





========== RESTART: C:/Python310/python_program/file_handling/read.py ==========
Hello World!

welcome to python 


Hell
Hello World!

He
['Hello World!\n', '\n', 'welcome to python \n', '\n']
['\n', 'welcome to python \n', '\n']

========== RESTART: C:/Python310/python_program/file_handling/read.py ==========
Hello World!

welcome to python 


Hell
Hello World!

He
['\n', 'welcome to python \n', '\n']

========== RESTART: C:/Python310/python_program/file_handling/read.py ==========
Hello World!

welcome to python 


Hell
Hello World!

He
Traceback (most recent call last):
  File "C:/Python310/python_program/file_handling/read.py", line 28, in <module>
    print(line.readline())
AttributeError: 'str' object has no attribute 'readline'

========== RESTART: C:/Python310/python_program/file_handling/read.py ==========
Hello World!

welcome to python 


Hell
Hello World!

He





========== RESTART: C:/Python310/python_program/file_handling/read.py ==========
Hello World!

welcome to python 


Hell
Hello World!

He
['\n', 'welcome to python \n', '\n']

========== RESTART: C:/Python310/python_program/file_handling/read.py ==========
Hello World!

welcome to python 


Hell
Hello World!

He
['Hello World!\n', '\n', 'welcome to python \n', '\n']

========== RESTART: C:/Python310/python_program/file_handling/read.py ==========
Hello World!

welcome to python 


Hell
Hello World!

He
['Hello World!\n', '\n', 'welcome to python \n', '\n']

========== RESTART: C:/Python310/python_program/file_handling/read.py ==========
test caseadding another line
test
test caseadding another line
te
['test caseadding another line']
test caseadding another line

========== RESTART: C:/Python310/python_program/file_handling/read.py ==========
test caseadding another line
test
test caseadding another line
te
['test caseadding another line']
test case
adding another line

=== RESTART: C:/Python310/python_program/file_handling/exception_handling.py ===
enter a value: r
Except block : Invalid input,enter numbers only

=== RESTART: C:/Python310/python_program/file_handling/exception_handling.py ===
enter a value: 3
Try block : number is  3

=== RESTART: C:/Python310/python_program/file_handling/exception_handling.py ===
enter a value: 5
Try block : number is  5

=== RESTART: C:/Python310/python_program/file_handling/exception_handling.py ===
enter a value: r
Except block : Invalid input,enter numbers only

=== RESTART: C:/Python310/python_program/file_handling/exception_handling.py ===
enter a value: 5
Try block : number is  5

=== RESTART: C:/Python310/python_program/file_handling/exception_handling.py ===
enter a value: r
Traceback (most recent call last):
  File "C:/Python310/python_program/file_handling/exception_handling.py", line 2, in <module>
    x = int(input("enter a value: "))
ValueError: invalid literal for int() with base 10: 'r'

During handling of the above exception, another exception occurred:

Traceback (most recent call last):
  File "C:/Python310/python_program/file_handling/exception_handling.py", line 5, in <module>
    print(Error)
NameError: name 'Error' is not defined. Did you mean: 'OSError'?

=== RESTART: C:/Python310/python_program/file_handling/exception_handling.py ===
enter a value: t
Traceback (most recent call last):
  File "C:/Python310/python_program/file_handling/exception_handling.py", line 2, in <module>
    x = int(input("enter a value: "))
ValueError: invalid literal for int() with base 10: 't'

During handling of the above exception, another exception occurred:

Traceback (most recent call last):
  File "C:/Python310/python_program/file_handling/exception_handling.py", line 5, in <module>
    print(error)
NameError: name 'error' is not defined. Did you mean: 'OSError'?

=== RESTART: C:/Python310/python_program/file_handling/exception_handling.py ===
enter a value: r
Except block : Invalid input,enter numbers only

=== RESTART: C:/Python310/python_program/file_handling/exception_handling.py ===
enter a value: 5
enter a value: 0
divide by zero exception is raised
division by zero

=== RESTART: C:/Python310/python_program/file_handling/exception_handling.py ===
enter a value: r
Except block : Invalid input,enter numbers only

=== RESTART: C:/Python310/python_program/file_handling/exception_handling.py ===
enter a value: r
Except block : Invalid input,enter numbers only

=== RESTART: C:/Python310/python_program/file_handling/exception_handling.py ===
enter a value: 4
Try block : number is  4
no exception

=== RESTART: C:/Python310/python_program/file_handling/exception_handling.py ===
enter a value: 5
Try block : number is  5
 entered value is :  5

=== RESTART: C:/Python310/python_program/file_handling/exception_handling.py ===
enter a value: r
Except block : Invalid input,enter numbers only
Traceback (most recent call last):
  File "C:/Python310/python_program/file_handling/exception_handling.py", line 35, in <module>
    print(" entered value is : ",x)
NameError: name 'x' is not defined

=== RESTART: C:/Python310/python_program/file_handling/exception_handling.py ===
enter a value: 5
enter the y value : 3
name 'div' is not defined
entered values are : 5 3

=== RESTART: C:/Python310/python_program/file_handling/exception_handling.py ===
enter a value: 5
enter the y value : 3
second try block is :  div is 1.6666666666666667
entered values are : 5 3

=== RESTART: C:/Python310/python_program/file_handling/exception_handling.py ===
enter a value: r
entered values are not integers
Traceback (most recent call last):
  File "C:/Python310/python_program/file_handling/exception_handling.py", line 48, in <module>
    print("entered values are :",x,y)
NameError: name 'x' is not defined

=== RESTART: C:/Python310/python_program/file_handling/exception_handling.py ===
enter a value: r
Traceback (most recent call last):
  File "C:/Python310/python_program/file_handling/exception_handling.py", line 39, in <module>
    x = int(input("enter a value: "))
ValueError: invalid literal for int() with base 10: 'r'

During handling of the above exception, another exception occurred:

Traceback (most recent call last):
  File "C:/Python310/python_program/file_handling/exception_handling.py", line 48, in <module>
    print("entered values are :",x,y)
NameError: name 'x' is not defined

=== RESTART: C:/Python310/python_program/file_handling/exception_handling.py ===
enter a value: r
entered values are not integers
Traceback (most recent call last):
  File "C:/Python310/python_program/file_handling/exception_handling.py", line 48, in <module>
    print("entered values are :",x,y)
NameError: name 'x' is not defined

=== RESTART: C:/Python310/python_program/file_handling/exception_handling.py ===
enter a value: 4
enter the y value : 2
second try block is :  div is 2.0
entered values are : 4 2

=== RESTART: C:/Python310/python_program/file_handling/exception_handling.py ===
enter a value: 10
x is not Eligible

=== RESTART: C:/Python310/python_program/file_handling/exception_handling.py ===
enter a value: 6
x is not Eligible

=== RESTART: C:/Python310/python_program/file_handling/exception_handling.py ===
enter a value: 21
x is eligible

=== RESTART: C:/Python310/python_program/file_handling/exception_handling.py ===
enter a value: 5
x is not Eligible

=== RESTART: C:/Python310/python_program/file_handling/exception_handling.py ===
enter a value: 5
x is eligible

=== RESTART: C:/Python310/python_program/file_handling/exception_handling.py ===
enter a value: 5
division by zero

=== RESTART: C:/Python310/python_program/file_handling/exception_handling.py ===
enter a value: 5
Exception Error :  division by zero

=== RESTART: C:/Python310/python_program/file_handling/exception_handling.py ===
enter a value: 5
x is eligible
Exception Error :  division by zero

=== RESTART: C:/Python310/python_program/file_handling/exception_handling.py ===
enter a value: 11
x is not Eligible

=== RESTART: C:/Python310/python_program/file_handling/exception_handling.py ===
enter a value: 11
x is not Eligible

=== RESTART: C:/Python310/python_program/file_handling/exception_handling.py ===
enter a value: 2
x is eligible
Exception Error :  division by zero
python --version
Traceback (most recent call last):
  File "<pyshell#0>", line 1, in <module>
    python --version
NameError: name 'python' is not defined

=== RESTART: C:/Python310/python_program/file_handling/exception_handling.py ===
enter a value: 4
x is eligible
Exception Error :  division by zero
--version
Traceback (most recent call last):
  File "<pyshell#1>", line 1, in <module>
    --version
NameError: name 'version' is not defined
python3.10 --vesrsion
SyntaxError: invalid syntax. Perhaps you forgot a comma?

=== RESTART: C:/Python310/python_program/file_handling/exception_handling.py ===
enter a value: 5
x is eligible
Exception Error :  division by zero

========== RESTART: C:\Python310\python_program\file_handling\read.py ==========
test case
adding another line
test
test case

te
['test case\n', 'adding another line']
test case
adding another line

========== RESTART: C:\Python310\python_program\file_handling\read.py ==========
test case
adding another linetest case
adding another line
test
test case

te
['test case\n', 'adding another linetest case\n', 'adding another line']
test case
adding another line

========== RESTART: C:\Python310\python_program\file_handling\read.py ==========
test case
adding another linetest case
adding another line
test
test case

te
['test case\n', 'adding another linetest case\n', 'adding another line']
test case
adding another line
Traceback (most recent call last):
  File "C:\Python310\python_program\file_handling\read.py", line 40, in <module>
    file = open("file2.txt",'x')
FileExistsError: [Errno 17] File exists: 'file2.txt'

========== RESTART: C:\Python310\python_program\file_handling\read.py ==========
test case
adding another linetest case
adding another line
test
test case

te
['test case\n', 'adding another linetest case\n', 'adding another line']
test case
adding another line

========== RESTART: C:\Python310\python_program\file_handling\read.py ==========
test case
adding another linetest case
adding another line
test
test case

te
['test case\n', 'adding another linetest case\n', 'adding another line']
test case
adding another line

========== RESTART: C:\Python310\python_program\file_handling\read.py ==========
test case
adding another linetest case
adding another line
test
test case

te
['test case\n', 'adding another linetest case\n', 'adding another line']
test case
adding another line
Traceback (most recent call last):
  File "C:\Python310\python_program\file_handling\read.py", line 41, in <module>
    file = open("file2.txt",'x')
FileExistsError: [Errno 17] File exists: 'file2.txt'

========== RESTART: C:\Python310\python_program\file_handling\read.py ==========
test case
adding another linetest case
adding another line
test
test case

te
['test case\n', 'adding another linetest case\n', 'adding another line']
test case
adding another line

========== RESTART: C:\Python310\python_program\file_handling\read.py ==========
test case
adding another linetest case
adding another line
test
test case

te
['test case\n', 'adding another linetest case\n', 'adding another line']
test case
adding another line
file not exists

========== RESTART: C:\Python310\python_program\file_handling\read.py ==========
test case
adding another linetest case
adding another line
test
test case

te
['test case\n', 'adding another linetest case\n', 'adding another line']
test case
adding another line
file exists

========== RESTART: C:\Python310\python_program\file_handling\read.py ==========
test case
adding another linetest case
adding another line
test
test case

te
['test case\n', 'adding another linetest case\n', 'adding another line']
test case
adding another line
file not exists
